Workbook

Sheet Dados
C10: JAN | D10: FEV | E10: MAR | F10: ABR | G10: MAI | H10: JUN | I10: JUL | J10: AGO | K10: SET | L10: OUT | M10: NOV | N10: DEZ | O10: TOTAL
A11: 1 | B11: Aluguel | C11: 700 | D11: 500 | E11: 500 | F11: 500 | G11: 500 | H11: 500 | I11: 500 | J11: 500 | K11: 500 | L11: 500 | M11: 500 | N11: 500 | O11: =SUM(C11:N11) -> 6200
A12: 2 | B12: Luz | C12: 157 | E12: 174.77 | F12: 176 | G12: 244 | H12: 223 | I12: 246 | J12: 326 | O12: =SUM(C12:N12) -> 1546.77
B13: Agua | C13: - | E13: 52 | F13: 77 | G13: 100 | H13: 100 | I13: 100 | J13: 100 | K13: 100 | L13: 100 | M13: 100 | N13: 100
A14: 3 | B14: Internet | C14: 67 | D14: 103 | E14: 99 | F14: 120 | G14: 120 | H14: 120 | I14: 99 | J14: 99 | K14: 99 | L14: 99 | M14: 99 | N14: 99 | O14: =SUM(C14:N14) -> 1223
A15: 4 | B15: Acordo Inter | C15: 53 | D15: 53 | E15: 53 | F15: 53 | G15: 53 | H15: 53 | I15: 53 | J15: 53 | K15: 53 | L15: 53 | M15: 53 | N15: 53 | O15: =SUM(C15:N15) -> 636
A16: 5 | B16: Viagem | C16: 260 | D16: 260 | E16: 260 | F16: 260 | G16: 260 | H16: 260 | I16: 260 | J16: 260 | K16: 260 | L16: 260 | M16: 260 | N16: 260 | O16: =SUM(C16:N16) -> 3120
A17: 6 | B17: Spotify | C17: 38 | D17: 38 | E17: 32 | F17: 32 | G17: 32 | H17: 32 | I17: 32 | J17: 32 | K17: 32 | L17: 32 | M17: 32 | N17: 32 | O17: =SUM(C17:N17) -> 396
A18: 7 | B18: Google One | C18: 10 | D18: 10 | E18: 10 | F18: 10 | G18: 10 | H18: 10 | I18: 10 | J18: 10 | K18: 10 | L18: 10 | M18: 10 | N18: 10 | O18: =SUM(C18:N18) -> 120
A19: 8 | B19: Meli+ | C19: 20 | D19: 20 | E19: 20 | F19: 60 | G19: - | H19: - | I19: 10 | J19: 10 | K19: 10 | L19: 10 | M19: 10 | N19: 10 | O19: =SUM(C19:N19) -> 180
A20: 9 | B20: YouTube Premium | C20: 27 | D20: 27 | E20: 27 | F20: 27 | G20: 27 | H20: 27 | I20: 27 | J20: 27 | K20: 27 | L20: 27 | M20: 27 | N20: 27 | O20: =SUM(C20:N20) -> 324
B21: Prime Video | C21: - | D21: - | E21: 20 | F21: 20 | G21: 20 | H21: 20 | I21: 20 | J21: 20 | K21: 20 | L21: 20 | M21: 20 | N21: 20 | O21: =SUM(C21:N21) -> 200
A22: 10 | O22: =SUM(C22:N22) -> 0
A23: 11 | O23: =SUM(C23:N23) -> 0
A24: 12 | O24: =SUM(C24:N24) -> 0
A25: 13 | O25: =SUM(C25:N25) -> 0
A26: 14 | O26: =SUM(C26:N26) -> 0
A27: 15 | O27: =SUM(C27:N27) -> 0
A28: 16 | O28: =SUM(C28:N28) -> 0
A29: 17 | O29: =SUM(C29:N29) -> 0
A30: 18 | B30: YouTube Premium | C30: 27 | D30: 27 | E30: 27 | F30: 27 | G30: 27 | H30: 27 | I30: 27 | J30: 27 | K30: 27 | L30: 27 | M30: 27 | N30: 27 | O30: =SUM(C30:N30) -> 324
A31: 19 | B31: Acordo Nubank | C31: - | D31: 87 | E31: 55 | F31: 55 | G31: 55 | H31: 55 | I31: 55 | J31: 55 | K31: 55 | L31: 55 | M31: 55 | N31: 55 | O31: =SUM(C31:N31) -> 637
A32: 20 | B32: Renata boticario | C32: 162 | D32: 162 | E32: 162 | F32: 162 | O32: =SUM(C32:N32) -> 648
A33: 21 | B33: Emprestimo Bradesco | C33: 177 | D33: 177 | E33: 180 | F33: 180 | G33: 180 | H33: 180 | I33: - | J33: - | K33: - | L33: - | M33: - | N33: - | O33: =SUM(C33:N33) -> 1074
A34: 22 | B34: Renata boticario | C34: 162 | D34: 162 | E34: 162 | F34: 162 | G34: 50 | H34: 50 | I34: - | J34: - | K34: - | L34: - | M34: - | N34: - | O34: =SUM(C34:N34) -> 748
A35: 23 | B35: Cartão de Credito Nubank | C35: 62 | D35: 62 | E35: 141 | F35: 400 | G35: 440 | H35: 400 | I35: 400 | J35: 275 | O35: =SUM(C35:N35) -> 2180
A36: 24 | B36: Bahia | C36: 86 | D36: 86 | E36: 86 | F36: 86 | I36: 93 | J36: 93 | K36: 93 | L36: 93 | M36: - | N36: - | O36: =SUM(C36:N36) -> 716
A37: 25 | B37: Lucas Cartão de Credito | C37: 96 | D37: 96 | E37: 96 | F37: - | G37: - | H37: - | I37: - | J37: - | K37: - | L37: - | M37: - | O37: =SUM(C37:N37) -> 288
A38: 26 | B38: Emprestimo Bradesco | C38: 70 | D38: 70 | E38: - | F38: - | G38: - | H38: - | J38: - | K38: - | L38: - | M38: - | N38: - | O38: =SUM(C38:N38) -> 140
A39: 27 | B39: Vivo | C39: - | D39: - | E39: 92 | F39: - | O39: =SUM(C39:N39) -> 92
A40: 28 | B40: Mayara | F40: 113 | G40: 113 | H40: 113 | I40: 113 | J40: - | K40: - | L40: - | M40: - | N40: - | O40: =SUM(C40:N40) -> 452
A41: 29 | B41: Emprestimo | G41: 213 | H41: 213 | I41: 213 | J41: 213 | K41: 213 | L41: 213 | O41: =SUM(C41:N41) -> 1278
A42: 30 | B42: Caio - Fone | I42: 105.5 | J42: 105.5 | K42: 105.5 | L42: 105.5 | O42: =SUM(C42:N42) -> 422
B43: Acordou cartão de crédito Bradesco | I43: 278.35 | J43: 278.35 | K43: 278.35 | L43: 278.35 | M43: 278.35 | N43: 278.35
B44: Gasto Mensal | C44: =SUM(C11:C42) -> 2174 | D44: =SUM(D11:D42) -> 1940 | E44: =SUM(E11:E42) -> 2248.77 | F44: =SUM(F11:F42) -> 2520 | G44: =SUM(G11:G42) -> 2444 | H44: =SUM(H11:H42) -> 2383 | I44: =SUM(I11:I43) -> 2641.85 | J44: =SUM(J11:J42) -> 2205.5 | K44: =SUM(K11:K42) -> 1604.5 | L44: =SUM(L11:L42) -> 1604.5 | M44: =SUM(M11:M42) -> 1193 | N44: =SUM(N11:N42) -> 1193 | O44: =SUM(O11:O42) -> 22944.77

Sheet Dashboard
C3: JAN | D3: FEV | E3: MAR | F3: ABR | G3: MAI | H3: JUN | I3: JUL | J3: AGO | K3: SET | L3: OUT | M3: NOV | N3: DEZ
B4: TOTAL | C4: =Dados!C44 -> 2174 | D4: =Dados!D44 -> 1940 | E4: =Dados!E44 -> 2248.77 | F4: =Dados!F44 -> 2520 | G4: =Dados!G44 -> 2444 | H4: =Dados!H44 -> 2383 | I4: =Dados!I44 -> 2641.85 | J4: =Dados!J44 -> 2205.5 | ... N4: =Dados!N44 -> 1193
B5: Comparação com mês anterior: | D5: =IFERROR((D4-C4)/C4,"-") -> -0.10763569 | E5: =IFERROR((E4-D4)/D4,"-") -> 0.15915979 | F5: =IFERROR((F4-E4)/E4,"-") -> 0.1206126 | G5: =IFERROR((G4-F4)/F4,"-") -> -0.03015873 | H5: =IFERROR((H4-G4)/G4,"-") -> -0.024959083 | I5: =IFERROR((I4-H4)/H4,"-") -> 0.10862358 | J5: =IFERROR((J4-I4)/I4,"-") -> -0.16516835 | K5: =IFERROR((K4-J4)/J4,"-") -> -0.27250057 | ... N5: =IFERROR((N4-M4)/M4,"-") -> 0
E9: Aluguel | H9: ← Clique na célula e escolha a despesa
C10: 1 | D10: 2 | E10: 3 | F10: 4 | G10: 5 | H10: 6 | I10: 7 | J10: 8 | K10: 9 | L10: 10 | M10: 11 | N10: 12
C11: JAN | D11: FEV | E11: MAR | F11: ABR | G11: MAI | H11: JUN | I11: JUL | J11: AGO | K11: SET | L11: OUT | M11: NOV | N11: DEZ
B12: TOTAL | C12: {=INDEX(Dados!$C$11:$N$42,MATCH($E$9,Dados!$B$11:$B$42,0),C10)} -> 700 | D12: {=INDEX(Dados!$C$11:$N$42,MATCH($E$9,Dados!$B$11:$B$42,0),D10)} -> 500 | E12: {=INDEX(Dados!$C$11:$N$42,MATCH($E$9,Dados!$B$11:$B$42,0),E10)} -> 500 | F12: {=INDEX(Dados!$C$11:$N$42,MATCH($E$9,Dados!$B$11:$B$42,0),F10)} -> 500 | G12: {=INDEX(Dados!$C$11:$N$42,MATCH($E$9,Dados!$B$11:$B$42,0),G10)} -> 500 | H12: {=INDEX(Dados!$C$11:$N$42,MATCH($E$9,Dados!$B$11:$B$42,0),H10)} -> 500 | I12: {=INDEX(Dados!$C$11:$N$42,MATCH($E$9,Dados!$B$11:$B$42,0),I10)} -> 500 | J12: {=INDEX(Dados!$C$11:$N$42,MATCH($E$9,Dados!$B$11:$B$42,0),J10)} -> 500 | ... N12: {=INDEX(Dados!$C$11:$N$42,MATCH($E$9,Dados!$B$11:$B$42,0),N10)} -> 500
B13: Comparação com mês anterior: | D13: =IFERROR((D12-C12)/C12,"-") -> -0.28571429 | E13: =IFERROR((E12-D12)/D12,"-") -> 0 | F13: =IFERROR((F12-E12)/E12,"-") -> 0 | G13: =IFERROR((G12-F12)/F12,"-") -> 0 | H13: =IFERROR((H12-G12)/G12,"-") -> 0 | I13: =IFERROR((I12-H12)/H12,"-") -> 0 | J13: =IFERROR((J12-I12)/I12,"-") -> 0 | K13: =IFERROR((K12-J12)/J12,"-") -> 0 | ... N13: =IFERROR((N12-M12)/M12,"-") -> 0

Sheet Investimento 
B1: JAN | C1: FEV | D1: MAR | E1: ABR | F1: MAI | G1: JUN | H1: JUL | I1: AGO | J1: SET | K1: OUT | L1: NOV | M1: DEZ
A2: Investimento | B2: 250 | C2: 250 | D2: 250 | E2: 250 | F2: 250 | G2: 250 | H2: 250 | I2: 250 | J2: 250 | K2: 250 | L2: 250 | M2: 250 | N2: =SUM(B2:M2) -> 3000

Sheet Config
A1: Parametros Globais
A2: Hoje | B2: =TODAY() -> 46219
A3: Mês Atual | B3: =MONTH(B2) -> 7
A6: Aba Dados: Card 1 | E6: Aba Dados: Card 3
A7: Título | B7: Mês Atual: | E7: Título | F7: Top 3 Gastos
A8: Mês | B8: =PROPER(TEXT(B2,"mmmm")) -> Julho
A10: Valor Mês | B10: {=INDEX(Dados!C44:N44,1,B3)} -> 2641.85
A11: Valor Mês Anterior | B11: {=INDEX(Dados!C44:N44,1,B3-1)} -> 2383
A12: Diferença | B12: =(B10-B11)/B11 -> 0.10862358
A13: =IF(B12>0,"↑ "&TEXT(B12,"0,0%"),"") -> ↑ 11% | B13: =IF(B12<0,"↓ "&TEXT(B12,"0,0%"),"")
A18: Aba Dados: Card 2
A19: Título | B19: Gastos Mensais
B20: JAN | C20: FEV | D20: MAR | E20: ABR | F20: MAI | G20: JUN | H20: JUL | I20: AGO | J20: SET | K20: OUT | L20: NOV | M20: DEZ
A21: Valor + Alto | B21: =IF(Dados!C44=LARGE(Dados!$C$39:$M$44,1),Dados!C44,0) -> 0 | C21: =IF(Dados!D44=LARGE(Dados!$C$39:$M$44,1),Dados!D44,0) -> 0 | D21: =IF(Dados!E44=LARGE(Dados!$C$39:$M$44,1),Dados!E44,0) -> 0 | E21: =IF(Dados!F44=LARGE(Dados!$C$39:$M$44,1),Dados!F44,0) -> 0 | F21: =IF(Dados!G44=LARGE(Dados!$C$39:$M$44,1),Dados!G44,0) -> 0 | G21: =IF(Dados!H44=LARGE(Dados!$C$39:$M$44,1),Dados!H44,0) -> 0 | H21: =IF(Dados!I44=LARGE(Dados!$C$39:$M$44,1),Dados!I44,0) -> 2641.85 | I21: =IF(Dados!J44=LARGE(Dados!$C$39:$M$44,1),Dados!J44,0) -> 0 | ... M21: =IF(Dados!N44=LARGE(Dados!$C$39:$M$44,1),Dados!N44,0) -> 0 | O21: Mínimo
A22: Valor + Baixo | B22: =IF(Dados!C44=$O$22,Dados!C44,0) -> 0 | C22: =IF(Dados!D44=$O$22,Dados!D44,0) -> 0 | D22: =IF(Dados!E44=$O$22,Dados!E44,0) -> 0 | E22: =IF(Dados!F44=$O$22,Dados!F44,0) -> 0 | F22: =IF(Dados!G44=$O$22,Dados!G44,0) -> 0 | G22: =IF(Dados!H44=$O$22,Dados!H44,0) -> 0 | H22: =IF(Dados!I44=$O$22,Dados!I44,0) -> 0 | I22: =IF(Dados!J44=$O$22,Dados!J44,0) -> 0 | ... M22: =IF(Dados!N44=$O$22,Dados!N44,0) -> 1193 | O22: {=MIN(IF(Dados!C44:N44>0,Dados!C44:N44))} -> 1193
A26: Aba Dados: Card 4
A27: Título | B27: Categoria com maior valor por ano
A28: Maior Categoria | B28: {=INDEX(Dados!B11:B42,MATCH(LARGE(Dados!O11:O42,1),Dados!O11:O42,0),1)} -> Aluguel
A29: Valor | B29: =LARGE(Dados!O11:O42,1) -> 6200
A30: % | B30: =IFERROR(B29/Dados!$O$44,"-") -> 0.27021408
A35: Aba Dashboard
A36: Título1 | B36: Gastos Mensais
A37: Título2 | B37: Gastos Mensais - Despesa Específica:
A38: Título3 | B38: Top 5 Gastos no ano
B41: Despesa | C41: Valor | D41: frequencia | E41: Valor final | H41: Top 5
B42: =Dados!B11 -> Aluguel | C42: =Dados!O11 -> 6200 | D42: =IF(C42=0,0,COUNTIF($C$42:$C$71,C42)) -> 1 | E42: =IF(D42>1,C42+ROW()/1000,C42) -> 6200 | H42: 1 | I42: =LARGE($E$42:$E$71,H42) -> 6200 | J42: =IF(I42=0,"-",INDEX($B$42:$B$71,MATCH(I42,$E$42:$E$71,0),1)) -> Aluguel
B43: =Dados!B12 -> Luz | C43: =Dados!O12 -> 1546.77 | D43: =IF(C43=0,0,COUNTIF($C$42:$C$71,C43)) -> 1 | E43: =IF(D43>1,C43+ROW()/1000,C43) -> 1546.77 | H43: 2 | I43: =LARGE($E$42:$E$71,H43) -> 3120 | J43: =IF(I43=0,"-",INDEX($B$42:$B$71,MATCH(I43,$E$42:$E$71,0),1)) -> Viagem
B44: =Dados!B14 -> Internet | C44: =Dados!O14 -> 1223 | D44: =IF(C44=0,0,COUNTIF($C$42:$C$71,C44)) -> 1 | E44: =IF(D44>1,C44+ROW()/1000,C44) -> 1223 | H44: 3 | I44: =LARGE($E$42:$E$71,H44) -> 2180 | J44: =IF(I44=0,"-",INDEX($B$42:$B$71,MATCH(I44,$E$42:$E$71,0),1)) -> Cartão de Credito Nubank
B45: =Dados!B15 -> Acordo Inter | C45: =Dados!O15 -> 636 | D45: =IF(C45=0,0,COUNTIF($C$42:$C$71,C45)) -> 1 | E45: =IF(D45>1,C45+ROW()/1000,C45) -> 636
B46: =Dados!B16 -> Viagem | C46: =Dados!O16 -> 3120 | D46: =IF(C46=0,0,COUNTIF($C$42:$C$71,C46)) -> 1 | E46: =IF(D46>1,C46+ROW()/1000,C46) -> 3120
B47: =Dados!B17 -> Spotify | C47: =Dados!O17 -> 396 | D47: =IF(C47=0,0,COUNTIF($C$42:$C$71,C47)) -> 1 | E47: =IF(D47>1,C47+ROW()/1000,C47) -> 396
B48: =Dados!B18 -> Google One | C48: =Dados!O18 -> 120 | D48: =IF(C48=0,0,COUNTIF($C$42:$C$71,C48)) -> 1 | E48: =IF(D48>1,C48+ROW()/1000,C48) -> 120
B49: =Dados!B19 -> Meli+ | C49: =Dados!O19 -> 180 | D49: =IF(C49=0,0,COUNTIF($C$42:$C$71,C49)) -> 1 | E49: =IF(D49>1,C49+ROW()/1000,C49) -> 180
B50: =Dados!B20 -> YouTube Premium | C50: =Dados!O20 -> 324 | D50: =IF(C50=0,0,COUNTIF($C$42:$C$71,C50)) -> 2 | E50: =IF(D50>1,C50+ROW()/1000,C50) -> 324.05
B51: =Dados!B22 | C51: =Dados!O22 -> 0 | D51: =IF(C51=0,0,COUNTIF($C$42:$C$71,C51)) -> 0 | E51: =IF(D51>1,C51+ROW()/1000,C51) -> 0
B52: =Dados!B23 | C52: =Dados!O23 -> 0 | D52: =IF(C52=0,0,COUNTIF($C$42:$C$71,C52)) -> 0 | E52: =IF(D52>1,C52+ROW()/1000,C52) -> 0
B53: =Dados!B24 | C53: =Dados!O24 -> 0 | D53: =IF(C53=0,0,COUNTIF($C$42:$C$71,C53)) -> 0 | E53: =IF(D53>1,C53+ROW()/1000,C53) -> 0
B54: =Dados!B25 | C54: =Dados!O25 -> 0 | D54: =IF(C54=0,0,COUNTIF($C$42:$C$71,C54)) -> 0 | E54: =IF(D54>1,C54+ROW()/1000,C54) -> 0
B55: =Dados!B26 | C55: =Dados!O26 -> 0 | D55: =IF(C55=0,0,COUNTIF($C$42:$C$71,C55)) -> 0 | E55: =IF(D55>1,C55+ROW()/1000,C55) -> 0
B56: =Dados!B27 | C56: =Dados!O27 -> 0 | D56: =IF(C56=0,0,COUNTIF($C$42:$C$71,C56)) -> 0 | E56: =IF(D56>1,C56+ROW()/1000,C56) -> 0
...
